Workbook

Sheet Summary
A1: No | B1: WO | C1: Work ID | D1: Unit Area | E1: Unit | F1: Type of Valve | G1: Manufacturer | H1: Valve Operated Type | I1: Serial No | J1: Tag Number (Valve No) | K1: Name Plate | L1: Date Recieved | M1: Service Type | N1: As received Report No | O1: Cert Report No | P1: Finding Report No | Q1: Service Report No | R1: Transport Mode | S1: Transport By | T1: Packaging | U1: Received By | V1: TRANSPORTATION (COMMENT) | W1: Inlet (Size) | X1: Outlet (Size) | Y1: Inlet (Type) | Z1: Outlet (Type) | AA1: Inlet (Rating) | AB1: Outlet (Rating) | AC1: Inlet Connection Condition | AD1: Outlet Connection Condition | AE1: Connection Major Damage | AF1: Valve Body Condition | AG1: Major Defect on Body | AH1: Overall Valve Condition
A2: 1 | B2: 81620162 | C2: AMSMV001 | D2: Ammonia | E2: 12 | F2: MOV | G2: SAMBO | H2: MOTOR OPERATED | J2: M237-12MOV-004 | K2: YES | L2: 45862 | M2: Gear Box Servicing & Valve Packing Replacement | N2: LENOG_PCFSSB_RR_001 | O2: LENOG_PCFSSB_CR_001 | P2: LENOG_PCFSSB_FR_001 | Q2: LENOG_PCFSSB_SR_001 | R2: LORRY | S2: TURCOMP | T2: WODDEN PALLET | U2: LENOG SDN BHD | V2: N/A | W2: 24" | X2: 24" | Y2: FLANGE | Z2: FLANGE | AA2: 150 | AB2: 150 | AC2: CORRODED | AD2: SLIGHTLY CORRODED | AE2: No | AF2: SCRACTHES | AG2: NO | AH2: ACCEPTABLE
A3: 2 | B3: 81620163 | C3: AMSMV002 | D3: Ammonia | E3: 14 | F3: MOV | G3: SAMBO | H3: MOTOR OPERATED | J3: M237-14MOV-001 | K3: YES | L3: 45863 | M3: Gear Box Servicing & Valve Packing Replacement | N3: LENOG_PCFSSB_RR_002 | O3: LENOG_PCFSSB_CR_002 | P3: LENOG_PCFSSB_FR_002 | Q3: LENOG_PCFSSB_SR_002 | R3: LORRY | S3: TURCOMP | T3: WODDEN PALLET | U3: LENOG SDN BHD | V3: HANDWHEEL DENTED DUE TO INPROPER SECURING | W3: 24 | X3: 24 | Y3: THREADED | Z3: THREADED | AA3: 300 | AB3: 300 | AC3: SLIGHTLY CORRODED | AD3: SEVERELY CORRODED | AE3: YES | AF3: SCRACTHES | AG3: YES | AH3: NOT ACCEPTABLE
A4: 3 | B4: 81620164 | C4: AMSMV003 | D4: Ammonia | E4: 14 | F4: MOV | G4: SAMBO | H4: MOTOR OPERATED | J4: M237-14MOV-002 | K4: YES | L4: 45864 | M4: Gear Box Servicing & Valve Packing Replacement | N4: LENOG_PCFSSB_RR_003 | O4: LENOG_PCFSSB_CR_003 | P4: LENOG_PCFSSB_FR_003 | Q4: LENOG_PCFSSB_SR_003 | W4: 20 | X4: 20 | AA4: 300 | AB4: 300
A5: 4 | B5: 81620165 | C5: AMSMV004 | D5: Ammonia | E5: 14 | F5: MOV | G5: SAMBO | H5: MOTOR OPERATED | J5: M237-14MOV-003 | M5: Gear Box Servicing & Valve Packing Replacement | N5: LENOG_PCFSSB_RR_004 | O5: LENOG_PCFSSB_CR_004 | P5: LENOG_PCFSSB_FR_004 | Q5: LENOG_PCFSSB_SR_004 | W5: 24 | X5: 24 | AA5: 300 | AB5: 300
A6: 5 | B6: 81620166 | C6: AMSMV005 | D6: Ammonia | E6: 14 | F6: MOV | G6: SAMBO | H6: MOTOR OPERATED | J6: M237-14MOV-004 | M6: Gear Box Servicing & Valve Packing Replacement | N6: LENOG_PCFSSB_RR_005 | O6: LENOG_PCFSSB_CR_005 | P6: LENOG_PCFSSB_FR_005 | Q6: LENOG_PCFSSB_SR_005 | W6: 28 | X6: 28 | AA6: 300 | AB6: 300
A7: 6 | B7: 81620167 | C7: AMSMV006 | D7: Ammonia | E7: 14 | F7: MOV | G7: SAMBO | H7: MOTOR OPERATED | J7: M237-14MOV-005 | M7: Gear Box Servicing & Valve Packing Replacement | N7: LENOG_PCFSSB_RR_006 | O7: LENOG_PCFSSB_CR_006 | P7: LENOG_PCFSSB_FR_006 | Q7: LENOG_PCFSSB_SR_006 | W7: 28 | X7: 28 | AA7: 300 | AB7: 300
A8: 7 | B8: 81620168 | C8: AMSMV007 | D8: Ammonia | E8: 15 | F8: MOV | G8: SAMBO | H8: MOTOR OPERATED | J8: M237-15MOV-011 | M8: Gear Box Servicing & Valve Packing Replacement | N8: LENOG_PCFSSB_RR_007 | O8: LENOG_PCFSSB_CR_007 | P8: LENOG_PCFSSB_FR_007 | Q8: LENOG_PCFSSB_SR_007 | W8: 24 | X8: 24 | AA8: 300 | AB8: 300
A9: 8 | B9: 81620169 | C9: AMSMV008 | D9: Ammonia | E9: 15 | F9: MOV | G9: DANAIS | H9: MOTOR OPERATED | J9: M237-15MOV-012A | M9: Gear Box Servicing & Valve Packing Replacement | N9: LENOG_PCFSSB_RR_008 | O9: LENOG_PCFSSB_CR_008 | P9: LENOG_PCFSSB_FR_008 | Q9: LENOG_PCFSSB_SR_008 | W9: 28 | X9: 28 | AA9: 150 | AB9: 150
A10: 9 | B10: 81620170 | C10: AMSMV009 | D10: Ammonia | E10: 15 | F10: MOV | G10: DANAIS | H10: MOTOR OPERATED | J10: M237-15MOV-012B | M10: Gear Box Servicing & Valve Packing Replacement | N10: LENOG_PCFSSB_RR_009 | O10: LENOG_PCFSSB_CR_009 | P10: LENOG_PCFSSB_FR_009 | Q10: LENOG_PCFSSB_SR_009 | W10: 28 | X10: 28 | AA10: 150 | AB10: 150
A11: 10 | B11: 81620171 | C11: AMSMV010 | D11: Ammonia | E11: 15 | F11: MOV | G11: DANAIS | H11: MOTOR OPERATED | J11: M237-15MOV-012C | M11: Gear Box Servicing & Valve Packing Replacement | N11: LENOG_PCFSSB_RR_010 | O11: LENOG_PCFSSB_CR_010 | P11: LENOG_PCFSSB_FR_010 | Q11: LENOG_PCFSSB_SR_010 | W11: 28 | X11: 28 | AA11: 150 | AB11: 150
A12: 11 | B12: 81620172 | C12: AMSMV011 | D12: Ammonia | E12: 16 | F12: MOV | G12: SAMBO | H12: MOTOR OPERATED | J12: M237-16MOV-002 | M12: Gear Box Servicing & Valve Packing Replacement | N12: LENOG_PCFSSB_RR_011 | O12: LENOG_PCFSSB_CR_011 | P12: LENOG_PCFSSB_FR_011 | Q12: LENOG_PCFSSB_SR_011 | W12: 20 | X12: 20 | AA12: 2500 | AB12: 2500
A13: 12 | B13: 81620174 | C13: AMSMV012 | D13: Ammonia | E13: 16 | F13: MOV | G13: SAMBO | H13: MOTOR OPERATED | J13: M237-16MOV-003 | M13: Gear Box Servicing & Valve Packing Replacement | N13: LENOG_PCFSSB_RR_012 | O13: LENOG_PCFSSB_CR_012 | P13: LENOG_PCFSSB_FR_012 | Q13: LENOG_PCFSSB_SR_012 | W13: 20 | X13: 20 | AA13: 600 | AB13: 600
A14: 13 | B14: 81620175 | C14: AMSMV013 | D14: Ammonia | E14: 17 | F14: MOV | G14: DANAIS | H14: MOTOR OPERATED | J14: M237-17MOV-002 | M14: Gear Box Servicing & Valve Packing Replacement | N14: LENOG_PCFSSB_RR_013 | O14: LENOG_PCFSSB_CR_013 | P14: LENOG_PCFSSB_FR_013 | Q14: LENOG_PCFSSB_SR_013 | W14: 24 | X14: 24 | AA14: 300 | AB14: 300
A15: 14 | B15: 81620176 | C15: AMSMV014 | D15: Ammonia | E15: 17 | F15: MOV | G15: SAMBO | H15: MOTOR OPERATED | J15: M237-17MOV-003 | M15: Gear Box Servicing & Valve Packing Replacement | N15: LENOG_PCFSSB_RR_014 | O15: LENOG_PCFSSB_CR_014 | P15: LENOG_PCFSSB_FR_014 | Q15: LENOG_PCFSSB_SR_014 | W15: 20 | X15: 20 | AA15: 300 | AB15: 300
A16: 15 | B16: 81620177 | C16: AMSMV015 | D16: Ammonia | E16: 19 | F16: MOV | G16: SAMBO | H16: MOTOR OPERATED | J16: M237-19MOV-001 | M16: Gear Box Servicing & Valve Packing Replacement | N16: LENOG_PCFSSB_RR_015 | O16: LENOG_PCFSSB_CR_015 | P16: LENOG_PCFSSB_FR_015 | Q16: LENOG_PCFSSB_SR_015 | W16: 16 | X16: 16 | AA16: 600 | AB16: 600
... A19: 18 | B19: 81620195 | C19: AMSMV018 | D19: Ammonia | E19: 53 | F19: MOV | G19: SAMBO | H19: MOTOR OPERATED | J19: M237-53MOV-111 | M19: Gear Box Servicing & Valve Packing Replacement | N19: LENOG_PCFSSB_RR_018 | O19: LENOG_PCFSSB_CR_018 | P19: LENOG_PCFSSB_FR_018 | Q19: LENOG_PCFSSB_SR_018 | W19: 20 | X19: 20 | AA19: 2500 | AB19: 2500
A20: 19 | B20: 81620180 | C20: URSMV001 | D20: Urea | E20: 32 | F20: MOV | G20: L&T/ ROTORK | H20: MOTOR OPERATED | J20: M237-32MOV-005A | M20: Gear Box Servicing & Valve Packing Replacement | N20: LENOG_PCFSSB_RR_019 | O20: LENOG_PCFSSB_CR_019 | P20: LENOG_PCFSSB_FR_019 | Q20: LENOG_PCFSSB_SR_019 | W20: 8 | X20: 8 | AA20: N/A | AB20: N/A
A21: 20 | B21: 81620181 | C21: URSMV002 | D21: Urea | E21: 32 | F21: MOV | G21: L&T/ ROTORK | H21: MOTOR OPERATED | J21: M237-32MOV-005B | M21: Gear Box Servicing & Valve Packing Replacement | N21: LENOG_PCFSSB_RR_020 | O21: LENOG_PCFSSB_CR_020 | P21: LENOG_PCFSSB_FR_020 | Q21: LENOG_PCFSSB_SR_020 | W21: 8 | X21: 8 | AA21: N/A | AB21: N/A
A22: 21 | B22: 81620182 | C22: URSMV003 | D22: Urea | E22: 32 | F22: MOV | G22: PARCOL | H22: MOTOR OPERATED | J22: M237-32MOV-007A | M22: Gear Box Servicing & Valve Packing Replacement | N22: LENOG_PCFSSB_RR_021 | O22: LENOG_PCFSSB_CR_021 | P22: LENOG_PCFSSB_FR_021 | Q22: LENOG_PCFSSB_SR_021 | W22: 8 | X22: 8 | AA22: N/A | AB22: N/A
A23: 22 | B23: 81620183 | C23: URSMV004 | D23: Urea | E23: 32 | F23: MOV | G23: PARCOL | H23: MOTOR OPERATED | J23: M237-32MOV-007B | M23: Gear Box Servicing & Valve Packing Replacement | N23: LENOG_PCFSSB_RR_022 | O23: LENOG_PCFSSB_CR_022 | P23: LENOG_PCFSSB_FR_022 | Q23: LENOG_PCFSSB_SR_022 | W23: 8 | X23: 8 | AA23: N/A | AB23: N/A
A24: 23 | B24: 81620184 | C24: URSMV005 | D24: Urea | E24: 32 | F24: MOV | G24: L&T/ ROTORK | H24: MOTOR OPERATED | J24: M237-32MOV-008 | M24: Gear Box Servicing & Valve Packing Replacement | W24: 2 | X24: 2 | AA24: N/A | AB24: N/A
A25: 24 | B25: 81620186 | C25: URSMV007 | D25: Urea | E25: 33 | F25: MOV | G25: PARCOL | H25: MOTOR OPERATED | J25: M237-33MOV-002 | M25: Gear Box Servicing & Valve Packing Replacement | W25: 8 | X25: 8 | AA25: N/A | AB25: N/A
A26: 25 | B26: 81620187 | C26: URSMV008 | D26: Urea | E26: 33 | F26: MOV | G26: PARCOL | H26: MOTOR OPERATED | J26: M237-33MOV-003 | M26: Gear Box Servicing & Valve Packing Replacement | W26: 8 | X26: 8 | AA26: N/A | AB26: N/A
A27: 26 | B27: 81620188 | C27: URSMV009 | D27: Urea | E27: 33 | F27: MOV | G27: PARCOL | H27: MOTOR OPERATED | J27: M237-33MOV-004 | M27: Gear Box Servicing & Valve Packing Replacement | W27: 8 | X27: 8 | AA27: N/A | AB27: N/A
A28: 27 | B28: 81620189 | C28: UTSMV001 | D28: Utility | E28: 48 | F28: MOV | G28: MACCHI/ AUMA | H28: MOTOR OPERATED | J28: M237-48MOV-751 | M28: Gear Box Servicing & Valve Packing Replacement | W28: 8 | X28: 8 | AA28: 600 | AB28: 600
A29: 28 | B29: 81620190 | C29: UTSMV002 | D29: Utility | E29: 48 | F29: MOV | G29: MACCHI/ AUMA | H29: MOTOR OPERATED | J29: M237-48MOV-851 | M29: Gear Box Servicing & Valve Packing Replacement | W29: 8 | X29: 8 | AA29: 600 | AB29: 600
A30: 29 | B30: 81620191 | C30: UTSMV003 | D30: Utility | E30: 48 | F30: MOV | G30: MACCHI/ AUMA | H30: MOTOR OPERATED | J30: M237-48MOV-951 | M30: Gear Box Servicing & Valve Packing Replacement | W30: 8 | X30: 8 | AA30: 600 | AB30: 600
A31: 30 | B31: 81620192 | C31: UTSMV004 | D31: Utility | E31: 52 | F31: MOV | G31: AUDCO INDIA/ SAMBO INDIA | H31: MOTOR OPERATED | J31: M237-52MOV-001A | M31: Gear Box Servicing & Valve Packing Replacement | W31: 10 | X31: 10 | AA31: 1500 | AB31: 1500
A32: 31 | B32: 81620193 | C32: UTSMV005 | D32: Utility | E32: 52 | F32: MOV | G32: AUDCO INDIA/ SAMBO INDIA | H32: MOTOR OPERATED | J32: M237-52MOV-001B | M32: Gear Box Servicing & Valve Packing Replacement | W32: 10 | X32: 10 | AA32: 1500 | AB32: 1500
A33: 32 | B33: 81620194 | C33: UTSMV006 | D33: Utility | E33: 52 | F33: MOV | G33: AUDCO INDIA/ SAMBO INDIA | H33: MOTOR OPERATED | J33: M237-52MOV-001C | M33: Gear Box Servicing & Valve Packing Replacement | W33: 10 | X33: 10 | AA33: 1500 | AB33: 1500
A34: 33 | B34: 81620196 | C34: UTSMV007 | D34: Utility | E34: 53 | F34: MOV | G34: MACCHI/ AUMA | H34: MOTOR OPERATED | J34: M237-53MOV-451 | M34: Gear Box Servicing & Valve Packing Replacement | W34: 10 | X34: 10 | AA34: 2500 | AB34: 2500
A35: 34 | B35: 81620197 | C35: UTSMV008 | D35: Utility | E35: 53 | F35: MOV | G35: MACCHI/ AUMA | H35: MOTOR OPERATED | J35: M237-53MOV-452 | M35: Gear Box Servicing & Valve Packing Replacement | W35: 2 | X35: 2 | AA35: 2500 | AB35: 2500
A36: 35 | B36: 81620198 | C36: UTSMV009 | D36: Utility | E36: 53 | F36: MOV | G36: MACCHI/ AUMA | H36: MOTOR OPERATED | J36: M237-53MOV-453 | M36: Gear Box Servicing & Valve Packing Replacement | W36: 6 | X36: 6 | AA36: 2500 | AB36: 2500
A37: 36 | B37: 81620200 | C37: UTSMV011 | D37: Utility | E37: 53 | F37: MOV | G37: MACCHI/ AUMA | H37: MOTOR OPERATED | J37: M237-53MOV-551 | M37: Gear Box Servicing & Valve Packing Replacement | W37: 10 | X37: 10 | AA37: 2500 | AB37: 2500
A38: 37 | B38: 81620202 | C38: UTSMV012 | D38: Utility | E38: 53 | F38: MOV | G38: MACCHI/ AUMA | H38: MOTOR OPERATED | J38: M237-53MOV-552 | M38: Gear Box Servicing & Valve Packing Replacement | W38: 2 | X38: 2 | AA38: 2500 | AB38: 2500
A39: 38 | B39: 81620203 | C39: UTSMV013 | D39: Utility | E39: 53 | F39: MOV | G39: MACCHI/ AUMA | H39: MOTOR OPERATED | J39: M237-53MOV-553 | M39: Gear Box Servicing & Valve Packing Replacement | W39: 6 | X39: 6 | AA39: 2500 | AB39: 2500
... A47: 46 | B47: 81620212 | C47: UTSMV022 | D47: Utility | E47: 55 | F47: MOV | G47: ISORIA | H47: MOTOR OPERATED | J47: M237-55MOV-001C | M47: Gear Box Servicing & Valve Packing Replacement | W47: 24 | X47: 24 | AA47: 150 | AB47: 150
A48: 47 | B48: 81753184 | C48: AMSAV001 | D48: Ammonia | E48: 15 | F48: ARV | G48: SCHROEDAHL | J48: M237-ARV-1501A | M48: Valve Overhaul at Workshop | N48: LENOG_PCFSSB_RR_001 | O48: LENOG_PCFSSB_CR_001 | P48: LENOG_PCFSSB_FR_001 | Q48: LENOG_PCFSSB_SR_001 | W48: 6x6x3 | X48: 6x6x3 | AA48: 600 | AB48: 600
A49: 48 | B49: 81753185 | C49: AMSAV002 | D49: Ammonia | E49: 15 | F49: ARV | G49: SCHROEDAHL | J49: M237-ARV-1501B | M49: Valve Overhaul at Workshop | N49: LENOG_PCFSSB_RR_002 | O49: LENOG_PCFSSB_CR_001 | P49: LENOG_PCFSSB_FR_001 | Q49: LENOG_PCFSSB_SR_001 | W49: 6x6x3 | X49: 6x6x3 | AA49: 600 | AB49: 600
...

Sheet Received Report
D1: PROVISION FOR MECHANICAL VALVE IN SITU PACKING REPLACEMENT, MECHANICAL VALVE OVERHAULING, AUTOMATIC RECIRCULATORY VALVE (ARV) SERVICING, AND MOV’S GEARBOX SERVICING FOR PCFS TA2025 | T1: 1
T2: Please Fill In
A13: RECEIVED REPORT
A15: CLIENT | D15: PETRONAS CHEMICALS FERTILISER SABAH SDN BHD
A16: PROJECT | D16: VALVE MAINTENANCE/REPAIR | I16: DOC NO | M16: =VLOOKUP($T1,Summary!$A$2:$AH$376,13,0)
A17: LOCATION | D17: SIPITANG SABAH | I17: SIZE INLET | M17: =VLOOKUP($T$1,Summary!$A$2:$AH$376,22,0) | N17: RATING | O17: =VLOOKUP($T$1,Summary!$A$2:$AH$376,26,0) | P17: INLET TYPE | R17: =VLOOKUP($T$1,Summary!$A$2:$AH$376,24,0)
A18: DATE IN | D18: =VLOOKUP($T$1,Summary!$A$2:$AH$376,11,0) | I18: SIZE OUTLET | M18: =VLOOKUP($T$1,Summary!$A$2:$AH$376,23,0) | N18: RATING | O18: =VLOOKUP($T$1,Summary!$A$2:$AH$376,27,0) | P18: OUTLET TYPE | R18: =VLOOKUP($T$1,Summary!$A$2:$AH$376,25,0)
A19: WO | D19: =VLOOKUP($T$1,Summary!$A$2:$AH$376,2,0) | I19: MANUFACTURER | M19: =VLOOKUP($T$1,Summary!$A$2:$AH$376,6,0)
A20: TAG NO | D20: =VLOOKUP($T$1,Summary!$A$2:$AH$376,9,0) | I20: TYPE OF VALVE | M20: =VLOOKUP($T$1,Summary!$A$2:$AH$376,5,0)
I21: VALVE OPERATED TYPE | M21: =VLOOKUP($T$1,Summary!$A$2:$AH$376,7,0)
A22: INSITU TESTING | D22: 0 | E22: SERVICE & REPAIR | I22: 0 | J22: TESTING ONLY | O22: REPLACE NEW VALVE | S22: 0
A23: TRANSPORTATION DETAILS
A24: TRANSPORT MODE | D24: =VLOOKUP($T$1,Summary!$A$2:$AH$376,17,0) | I24: PACKAGING | M24: =VLOOKUP($T$1,Summary!$A$2:$AH$376,19,0)
A25: TRANSPORT BY | D25: =VLOOKUP($T$1,Summary!$A$2:$AH$376,18,0) | I25: RECEIVED BY | M25: =VLOOKUP($T$1,Summary!$A$2:$AH$376,20,0)
A26: COMMENT ON TRANSPORTATION IF ANY | G26: =VLOOKUP($T$1,Summary!$A$2:$AH$376,21,0)
A27: AS RECEIVED VALVE:
A42: AS RECEIVED VALVE CONDITION
A43: INLET CONNECTION TYPE | F43: =VLOOKUP($T$1,Summary!$A$2:$AH$376,24,0) | K43: OUTLET CONNECTION TYPE | P43: =VLOOKUP($T$1,Summary!$A$2:$AH$376,25,0)
A44: NAMEPLATE | F44: =VLOOKUP($T$1,Summary!$A$2:$AH$376,10,0) | K44: TAG NUMBER/PLATE | P44: =VLOOKUP($T$1,Summary!$A$2:$AH$376,9,0)
A45: INLET CONNECTION CONDITION | F45: =VLOOKUP($T$1,Summary!$A$2:$AH$376,28,0) | K45: OUTLET CONNECTION CONDITION | P45: =VLOOKUP($T$1,Summary!$A$2:$AH$376,29,0)
A46: CONNECTION MAJOR DEFECT/DAMAGE | F46: =VLOOKUP($T$1,Summary!$A$2:$AH$376,30,0)
A47: VALVE BODY CONDITION | F47: =VLOOKUP($T$1,Summary!$A$2:$AH$376,31,0) | K47: MAJOR DEFECT ON BODY | P47: =VLOOKUP($T$1,Summary!$A$2:$AH$376,32,0)
A48: OVERALL VALVE CONDITION
A49: =VLOOKUP($T$1,Summary!$A$2:$AH$376,33,0)
A53: DETAILS PICTURE
A54: INLET CONNECTION | K54: OUTLET CONNECTION
A55: DEFECT CONNECTION (IF ANY) | K55: DEFECT ON BODY (IF ANY) | P55: =Summary!AO5
A56: PREPARED BY | G56: CLIENT REPRESENTATIVE | M56: APPROVED BY
A62: NAME: | G62: NAME: | M62: NAME:
A63: DATE: | B63: =TODAY() | G63: DATE: | M63: DATE:

Sheet Finding Report
D1: PROVISION FOR MECHANICAL VALVE IN SITU PACKING REPLACEMENT, MECHANICAL VALVE OVERHAULING, AUTOMATIC RECIRCULATORY VALVE (ARV) SERVICING, AND MOV’S GEARBOX SERVICING FOR PCFS TA2025 | T1: ='Received Report'!T1
A13: FINDING REPORT
A15: CLIENT | D15: PETRONAS CHEMICALS FERTILISER SABAH SDN BHD
A16: PROJECT | D16: VALVE MAINTENANCE/REPAIR | I16: DOC NO | M16: =VLOOKUP($T1,Summary!$A$2:$AH$376,13,0)
A17: LOCATION | D17: SIPITANG SABAH | I17: SIZE INLET | M17: =VLOOKUP($T$1,Summary!$A$2:$AH$376,22,0) | N17: RATING | O17: =VLOOKUP($T$1,Summary!$A$2:$AH$376,26,0) | P17: INLET TYPE | R17: =VLOOKUP($T$1,Summary!$A$2:$AH$376,24,0)
A18: DATE IN | D18: =VLOOKUP($T$1,Summary!$A$2:$AH$376,11,0) | I18: SIZE OUTLET | M18: =VLOOKUP($T$1,Summary!$A$2:$AH$376,23,0) | N18: RATING | O18: =VLOOKUP($T$1,Summary!$A$2:$AH$376,27,0) | P18: OUTLET TYPE | R18: =VLOOKUP($T$1,Summary!$A$2:$AH$376,25,0)
A19: WO | D19: =VLOOKUP($T$1,Summary!$A$2:$AH$376,2,0) | I19: MANUFACTURER | M19: =VLOOKUP($T$1,Summary!$A$2:$AH$376,6,0)
A20: TAG NO | D20: =VLOOKUP($T$1,Summary!$A$2:$AH$376,9,0) | I20: TYPE OF VALVE | M20: =VLOOKUP($T$1,Summary!$A$2:$AH$376,5,0)
I21: VALVE OPERATED TYPE | M21: =VLOOKUP($T$1,Summary!$A$2:$AH$376,7,0)
A22: INSITU TESTING | D22: 0 | E22: SERVICE & REPAIR | I22: 0 | J22: TESTING ONLY | O22: REPLACE NEW VALVE | S22: 0
A23: AS RECEIVED VISUAL INSPECTION (EXTERNAL)
A24: DESCRIPTION | F24: CONDITION | I24: ACTION | N24: REMARK
A25: GENERAL APPEARANCE | F25: ='Received Report'!F47 | I25: TO REPLACE NEW | N25: NO SPARE KIT
A26: NAMEPLATE | F26: AVAILABLE | I26: TO BUILD UP & MACHINE | N26: NEED TO REPLACED
A27: OVERALL FLANGES/CONNECTION CONDT'N | F27: MISSING | I27: TO LAPPING | N27: NO SPARE KIT
A28: STEM | F28: NEW | I28: TO LAPPING | N28: NEED TO REPLACED
A29: VALVE BODY | F29: NEW | I29: N/A | N29: NEED TO REPLACED
A30: HANDWHEELS | F30: NOT APPLICABLE | I30: TO BUILD UP & MACHINE | N30: NO SPARE KIT
A31: VALVE BONNET | F31: IN PLACED | I31: CLEANING | N31: NO SPARE KIT
A32: YOKE | F32: DIRTY | I32: TO BUILD UP & MACHINE | N32: N/A
A33: BOLT NUT | F33: NEW | I33: TO REPLACE NEW | N33: BADLY DAMAGED
A34: INLET/OUTLET FLANGE | F34: OK | I34: N/A | N34: REUSEABLE
A35: GEAR BOX/ACTUATOR | F35: NOT AVAILABLE | I35: N/A | N35: N/A
A36: PRE-TEST (HYDROTEST/LEAKED TEST)
A37: TYPE OF TEST | G37: HYDROTEST | K37: TEST MEDIUM | O37: WATER
A38: DECRIPTION | G38: PRESSURE | K38: DURATION | O38: RESULT & REMARKS
A39: A | B39: SHELL | G39: 10 Bar | K39: 15 Minutes | O39: NO LEAK & ACCEPTED
A40: B | B40: BACKSEAT | G40: 10 Bar | K40: 15 Minutes | O40: NO LEAK & ACCEPTED
A41: C | B41: SEAT | G41: 10 Bar | K41: 15 Minutes | O41: NO LEAK & ACCEPTED
A42: TEST ACCORDANCE TO | G42: API 2000
A43: INTERNAL PARTS INSPECTION
A44: DESCRIPTION | F44: CONDITION | I44: ACTION | N44: REMARK
A45: BODY | F45: MAJOR SCRATCH | I45: NOT APPLICABLE | N45: N/A
A46: BONNET | F46: WORN OUT | I46: TO LAPPED | N46: NEED TO REPLACED
A47: YOKE | F47: WORN OUT | I47: TO LAPPED | N47: NO SPARE KIT
A48: DISC | F48: LOOSED | I48: NOT APPLICABLE | N48: NEED TO REPLACED
A49: SEAT | F49: NOT VISSIBLE | I49: CLEANING | N49: N/A
A50: BONNET GASKET | F50: MAJOR SCRATCH | I50: TO MACHINED | N50: N/A
A51: STEM | F51: LOOSED | I51: TO BUILD UP & MACHINE | N51: BADLY DAMAGED
A52: WHEEL NUT | F52: WORN OUT | I52: TO MACHINED | N52: N/A
...

Sheet Serviced Report
D1: PROVISION FOR MECHANICAL VALVE IN SITU PACKING REPLACEMENT, MECHANICAL VALVE OVERHAULING, AUTOMATIC RECIRCULATORY VALVE (ARV) SERVICING, AND MOV’S GEARBOX SERVICING FOR PCFS TA2025 | T1: ='Finding Report'!T1
A13: RECEIVED REPORT
A15: CLIENT | D15: PETRONAS CHEMICALS FERTILISER SABAH SDN BHD
A16: PROJECT | D16: VALVE MAINTENANCE/REPAIR | I16: DOC NO | M16: =VLOOKUP($T1,Summary!$A$2:$AH$376,13,0)
A17: LOCATION | D17: SIPITANG SABAH | I17: SIZE INLET | M17: =VLOOKUP($T$1,Summary!$A$2:$AH$376,22,0) | N17: RATING | O17: =VLOOKUP($T$1,Summary!$A$2:$AH$376,26,0) | P17: INLET TYPE | R17: =VLOOKUP($T$1,Summary!$A$2:$AH$376,24,0)
A18: DATE IN | D18: =VLOOKUP($T$1,Summary!$A$2:$AH$376,11,0) | I18: SIZE OUTLET | M18: =VLOOKUP($T$1,Summary!$A$2:$AH$376,23,0) | N18: RATING | O18: =VLOOKUP($T$1,Summary!$A$2:$AH$376,27,0) | P18: OUTLET TYPE | R18: =VLOOKUP($T$1,Summary!$A$2:$AH$376,25,0)
A19: WO | D19: =VLOOKUP($T$1,Summary!$A$2:$AH$376,2,0) | I19: MANUFACTURER | M19: =VLOOKUP($T$1,Summary!$A$2:$AH$376,6,0)
A20: TAG NO | D20: =VLOOKUP($T$1,Summary!$A$2:$AH$376,9,0) | I20: TYPE OF VALVE | M20: =VLOOKUP($T$1,Summary!$A$2:$AH$376,5,0)
I21: VALVE OPERATED TYPE | M21: =VLOOKUP($T$1,Summary!$A$2:$AH$376,7,0)
A22: INSITU TESTING | D22: 0 | E22: SERVICE & REPAIR | I22: 0 | J22: TESTING ONLY | O22: REPLACE NEW VALVE | S22: 0
A23: AS RECEIVED VISUAL INSPECTION
A24: DESCRIPTION | F24: CONDITION | I24: ACTION | N24: REMARK
A25: ='Finding Report'!A25 | F25: ='Received Report'!F43 | I25: ='Finding Report'!I25 | N25: SERVICED & CLEANED
A26: ='Finding Report'!A26 | F26: ='Received Report'!F44 | I26: ='Finding Report'!I26 | N26: N/A
A27: ='Finding Report'!A27 | F27: ='Finding Report'!F27 | I27: ='Finding Report'!I27 | N27: SERVICED & CLEANED
A28: ='Finding Report'!A28 | F28: ='Finding Report'!F28 | I28: ='Finding Report'!I28 | N28: N/A
A29: ='Finding Report'!A29 | F29: ='Finding Report'!F29 | I29: ='Finding Report'!I29 | N29: SERVICED & CLEANED
A30: ='Finding Report'!A30 | F30: ='Finding Report'!F30 | I30: ='Finding Report'!I30 | N30: N/A
A31: ='Finding Report'!A31 | F31: ='Finding Report'!F31 | I31: ='Finding Report'!I31 | N31: SERVICED & CLEANED
A32: ='Finding Report'!A32 | F32: ='Finding Report'!F32 | I32: ='Finding Report'!I32 | N32: NO SPARE
A33: ='Finding Report'!A33 | F33: ='Finding Report'!F33 | I33: ='Finding Report'!I33 | N33: NO SPARE
A34: ='Finding Report'!A35 | F34: ='Finding Report'!F35 | I34: ='Finding Report'!I35 | N34: SERVICED & CLEANED
A35: INTERNAL PARTS INSPECTION
A36: DESCRIPTION | F36: CONDITION | I36: ACTION | N36: REMARK
A37: ='Finding Report'!A45 | F37: ='Finding Report'!F45 | I37: ='Finding Report'!I45 | N37: N/A
A38: ='Finding Report'!A46 | F38: ='Finding Report'!F46 | I38: ='Finding Report'!I46 | N38: SERVICED & CLEANED
A39: ='Finding Report'!A47 | F39: ='Finding Report'!F47 | I39: ='Finding Report'!I47 | N39: SERVICED & CLEANED
A40: ='Finding Report'!A48 | F40: ='Finding Report'!F48 | I40: ='Finding Report'!I48 | N40: SERVICED & CLEANED
A41: ='Finding Report'!A49 | F41: ='Finding Report'!F49 | I41: ='Finding Report'!I49 | N41: SERVICED & CLEANED
A42: ='Finding Report'!A50 | F42: ='Finding Report'!F50 | I42: ='Finding Report'!I50 | N42: SERVICED & CLEANED
A43: ='Finding Report'!A51 | F43: ='Finding Report'!F51 | I43: ='Finding Report'!I51 | N43: SERVICED & CLEANED
A44: ='Finding Report'!A52 | F44: ='Finding Report'!F52 | I44: ='Finding Report'!I52 | N44: SERVICED & CLEANED
A45: ='Finding Report'!A53 | F45: ='Finding Report'!F53 | I45: ='Finding Report'!I53 | N45: REUSED
A46: ='Finding Report'!A54 | F46: ='Finding Report'!F54 | I46: ='Finding Report'!I54 | N46: MACHINED NEW
A47: ='Finding Report'!A55 | F47: ='Finding Report'!F55 | I47: ='Finding Report'!I55 | N47: SERVICED & CLEANED
A48: ='Finding Report'!A56 | F48: ='Finding Report'!F56 | I48: ='Finding Report'!I56 | N48: NEW
A49: ='Finding Report'!A57 | F49: ='Finding Report'!F57 | I49: ='Finding Report'!I57
A50: ='Finding Report'!A58 | F50: ='Finding Report'!F58 | I50: ='Finding Report'!I58
A51: ADDITIONAL COMMENT
A57: DETAILS PICTURE OF SERVICED ITEM
...

Sheet Hydrotest Only
D1: PROVISION FOR MECHANICAL VALVE IN SITU PACKING REPLACEMENT, MECHANICAL VALVE OVERHAULING, AUTOMATIC RECIRCULATORY VALVE (ARV) SERVICING, AND MOV’S GEARBOX SERVICING FOR PCFS TA2025 | T1: ='Serviced Report'!T1
A13: RECEIVED REPORT
A15: CLIENT | D15: PETRONAS CHEMICALS FERTILISER SABAH SDN BHD
A16: PROJECT | D16: VALVE MAINTENANCE/REPAIR | I16: DOC NO | M16: =VLOOKUP($T1,Summary!$A$2:$AH$376,13,0)
A17: LOCATION | D17: SIPITANG SABAH | I17: SIZE INLET | M17: =VLOOKUP($T$1,Summary!$A$2:$AH$376,22,0) | N17: RATING | O17: =VLOOKUP($T$1,Summary!$A$2:$AH$376,26,0) | P17: INLET TYPE | R17: =VLOOKUP($T$1,Summary!$A$2:$AH$376,24,0)
A18: DATE IN | D18: =VLOOKUP($T$1,Summary!$A$2:$AH$376,11,0) | I18: SIZE OUTLET | M18: =VLOOKUP($T$1,Summary!$A$2:$AH$376,23,0) | N18: RATING | O18: =VLOOKUP($T$1,Summary!$A$2:$AH$376,27,0) | P18: OUTLET TYPE | R18: =VLOOKUP($T$1,Summary!$A$2:$AH$376,25,0)
A19: WO | D19: =VLOOKUP($T$1,Summary!$A$2:$AH$376,2,0) | I19: MANUFACTURER | M19: =VLOOKUP($T$1,Summary!$A$2:$AH$376,6,0)
A20: TAG NO | D20: =VLOOKUP($T$1,Summary!$A$2:$AH$376,9,0) | I20: TYPE OF VALVE | M20: =VLOOKUP($T$1,Summary!$A$2:$AH$376,5,0)
I21: VALVE OPERATED TYPE | M21: =VLOOKUP($T$1,Summary!$A$2:$AH$376,7,0)
A22: INSITU TESTING | D22: 0 | E22: SERVICE & REPAIR | I22: 0 | J22: TESTING ONLY | O22: REPLACE NEW VALVE | S22: 0
A23: AS RECEIVED VISUAL INSPECTION & SERVICES
A24: DESCRIPTION | F24: CONDITION | I24: ACTION | N24: REMARK
A25: ='Finding Report'!A25 | F25: ='Received Report'!F47 | I25: SAT ONLY | N25: OK
A26: ='Finding Report'!A26 | F26: ='Received Report'!F44 | I26: SAT ONLY | N26: OK
A27: ='Finding Report'!A27 | F27: ='Received Report'!F45 | I27: SAT ONLY | N27: OK
A28: ='Finding Report'!A28 | F28: ='Finding Report'!F28 | I28: SAT ONLY | N28: OK
A29: ='Finding Report'!A29 | F29: ='Finding Report'!F29 | I29: SAT ONLY | N29: OK
A30: ='Finding Report'!A30 | F30: ='Finding Report'!F30 | I30: SAT ONLY | N30: OK
A31: ='Finding Report'!A31 | F31: ='Finding Report'!F31 | I31: SAT ONLY | N31: OK
A32: ='Finding Report'!A32 | F32: ='Finding Report'!F32 | I32: SAT ONLY | N32: OK
A33: ='Finding Report'!A33 | F33: ='Finding Report'!F33 | I33: SAT ONLY | N33: OK
A34: ='Finding Report'!A35 | F34: ='Finding Report'!F35 | I34: SAT ONLY | N34: OK
A35: PRE-TEST (HYDROTEST/LEAKED TEST) - AS RECEIVED
A36: TYPE OF TEST | G36: ='Finding Report'!G37 | K36: TEST MEDIUM | O36: ='Finding Report'!O37
A37: DESCRIPTION | G37: PRESSURE | K37: DURATION | O37: RESULT & REMARKS
A38: A | B38: SHELL | G38: 150 BAR | K38: 1MIN | O38: NO LEAK/PRESSURE DROP-ACCEPTED
A39: B | B39: BACKSEAT | G39: 110 BAR | K39: 1MIN | O39: NO LEAK/PRESSURE DROP-ACCEPTED
A40: C | B40: SEAT A | G40: 110 BAR | K40: 1MIN | O40: NO LEAK/PRESSURE DROP-ACCEPTED
A41: D | B41: SEAT B | G41: 110 BAR | K41: 1MIN | O41: NO LEAK/PRESSURE DROP-ACCEPTED
A42: TEST ACCORDANCE TO | G42: API 598
A43: INTERNAL PARTS INSPECTION & SERVICES
A44: DESCRIPTION | F44: CONDITION | I44: ACTION | N44: REMARK
A45: ='Finding Report'!A45 | F45: NO SERVICING- SAT ONLY
A46: ='Finding Report'!A46
A47: ='Finding Report'!A47
A48: ='Finding Report'!A48
A49: ='Finding Report'!A49
A50: ='Finding Report'!A50
A51: ='Finding Report'!A51
A52: ='Finding Report'!A52
...

Sheet Valve Cert
D1: PROVISION FOR MECHANICAL VALVE IN SITU PACKING REPLACEMENT, MECHANICAL VALVE OVERHAULING, AUTOMATIC RECIRCULATORY VALVE (ARV) SERVICING, AND MOV’S GEARBOX SERVICING FOR PCFS TA2025 | T1: ='Hydrotest Only'!T1
A13: RECEIVED REPORT
A15: CLIENT | D15: PETRONAS CHEMICALS FERTILISER SABAH SDN BHD
A16: PROJECT | D16: VALVE MAINTENANCE/REPAIR | I16: DOC NO | M16: =VLOOKUP($T1,Summary!$A$2:$AH$376,13,0)
A17: LOCATION | D17: SIPITANG SABAH | I17: SIZE INLET | M17: =VLOOKUP($T$1,Summary!$A$2:$AH$376,22,0) | N17: RATING | O17: =VLOOKUP($T$1,Summary!$A$2:$AH$376,26,0) | P17: INLET TYPE | R17: =VLOOKUP($T$1,Summary!$A$2:$AH$376,24,0)
A18: DATE IN | D18: =VLOOKUP($T$1,Summary!$A$2:$AH$376,11,0) | I18: SIZE OUTLET | M18: =VLOOKUP($T$1,Summary!$A$2:$AH$376,23,0) | N18: RATING | O18: =VLOOKUP($T$1,Summary!$A$2:$AH$376,27,0) | P18: OUTLET TYPE | R18: =VLOOKUP($T$1,Summary!$A$2:$AH$376,25,0)
A19: WO | D19: =VLOOKUP($T$1,Summary!$A$2:$AH$376,2,0) | I19: MANUFACTURER | M19: =VLOOKUP($T$1,Summary!$A$2:$AH$376,6,0)
A20: TAG NO | D20: =VLOOKUP($T$1,Summary!$A$2:$AH$376,9,0) | I20: TYPE OF VALVE | M20: =VLOOKUP($T$1,Summary!$A$2:$AH$376,5,0) | V20: SER
I21: VALVE OPERATED TYPE | M21: =VLOOKUP($T$1,Summary!$A$2:$AH$376,7,0)
A22: INSITU TESTING | D22: 0 | E22: SERVICE & REPAIR | I22: 0 | J22: OVERHAUL | O22: REPLACE NEW VALVE | S22: 0
A23: AS RECEIVED VISUAL INSPECTION & SERVICES
A24: DESCRIPTION | F24: CONDITION | I24: ACTION | N24: REMARK
A25: ='Finding Report'!A25 | F25: ='Received Report'!F47 | I25: ='Finding Report'!I25 | N25: ='Serviced Report'!N25
A26: ='Finding Report'!A26 | F26: ='Received Report'!F44 | I26: ='Finding Report'!I26 | N26: ='Serviced Report'!N26
A27: ='Finding Report'!A27 | F27: ='Received Report'!F45 | I27: ='Finding Report'!I27 | N27: ='Serviced Report'!N27
A28: ='Finding Report'!A28 | F28: ='Finding Report'!F28 | I28: ='Finding Report'!I28 | N28: ='Serviced Report'!N28
A29: ='Finding Report'!A29 | F29: ='Finding Report'!F29 | I29: ='Finding Report'!I29 | N29: ='Serviced Report'!N29
A30: ='Finding Report'!A30 | F30: ='Finding Report'!F30 | I30: ='Finding Report'!I30 | N30: ='Serviced Report'!N30
A31: ='Finding Report'!A31 | F31: ='Finding Report'!F31 | I31: ='Finding Report'!I31 | N31: ='Serviced Report'!N31
A32: ='Finding Report'!A32 | F32: ='Finding Report'!F32 | I32: ='Finding Report'!I32 | N32: ='Serviced Report'!N32
A33: ='Finding Report'!A33 | F33: ='Finding Report'!F33 | I33: ='Finding Report'!I33 | N33: ='Serviced Report'!N33
A34: ='Finding Report'!A35 | F34: ='Finding Report'!F35 | I34: ='Finding Report'!I35 | N34: ='Serviced Report'!N34
A35: PRE-TEST (HYDROTEST/LEAKED TEST) - AS RECEIVED
A36: TYPE OF TEST | G36: ='Finding Report'!G37 | K36: TEST MEDIUM | O36: ='Finding Report'!O37
A37: DESCRIPTION | G37: PRESSURE | K37: DURATION | O37: RESULT & REMARKS
A38: A | B38: SHELL | G38: ='Finding Report'!G39 | K38: ='Finding Report'!K39 | O38: ='Finding Report'!O39
A39: B | B39: BACKSEAT | G39: ='Finding Report'!G40 | K39: ='Finding Report'!K40 | O39: ='Finding Report'!O40
A40: C | B40: SEAT | G40: ='Finding Report'!G41 | K40: ='Finding Report'!K41 | O40: ='Finding Report'!O41
A41: TEST ACCORDANCE TO | G41: API 2000
A42: INTERNAL PARTS INSPECTION & SERVICES
A43: DESCRIPTION | F43: CONDITION | I43: ACTION | N43: REMARK
A44: ='Finding Report'!A45 | F44: ='Finding Report'!F45 | I44: ='Finding Report'!I45 | N44: ='Serviced Report'!N37
A45: ='Finding Report'!A46 | F45: ='Finding Report'!F46 | I45: ='Finding Report'!I46 | N45: ='Serviced Report'!N38
A46: ='Finding Report'!A47 | F46: ='Finding Report'!F47 | I46: ='Finding Report'!I47 | N46: ='Serviced Report'!N39
A47: ='Finding Report'!A48 | F47: ='Finding Report'!F48 | I47: ='Finding Report'!I48 | N47: ='Serviced Report'!N40
A48: ='Finding Report'!A49 | F48: ='Finding Report'!F49 | I48: ='Finding Report'!I49 | N48: ='Serviced Report'!N41
A49: ='Finding Report'!A50 | F49: ='Finding Report'!F50 | I49: ='Finding Report'!I50 | N49: ='Serviced Report'!N42
A50: ='Finding Report'!A51 | F50: ='Finding Report'!F51 | I50: ='Finding Report'!I51 | N50: ='Serviced Report'!N43
A51: ='Finding Report'!A52 | F51: ='Finding Report'!F52 | I51: ='Finding Report'!I52 | N51: ='Serviced Report'!N44
A52: ='Finding Report'!A53 | F52: ='Finding Report'!F53 | I52: ='Finding Report'!I53 | N52: ='Serviced Report'!N45
...

Sheet Valve Repacking Checklist
C1: XX TURNAROUND XX | R1: 8
C3: Checklist for QC-MST-Valve Repacking
A6: Equipment Tag No. | C6: =VLOOKUP(R1,Summary!A1:AH376,9,0) | E6: Work ID | G6: =VLOOKUP(R1,Summary!A1:AH376,2,0) | J6: Contractor | L6: LENOG SDN BHD | O6: Date | P6: =TODAY()
A8: Work Description | C8: =VLOOKUP(R1,Summary!A1:AH376,12,0)
A10: QUALITY CHECKS
A13: No. | B13: Action | K13: Accepted | M13: NA | N13: Remarks
A15: 1 | B15: Packing of gland
B17: a) Ensure size, material of packing is correct per specification/datasheet
B19: b) Visually inspect stem & stuffing box condition and free from defect
B21: c) Measure existing gland nut (ensure number of thread similar before and after)
B23: d) Cleanliness of the stuffing box accepted
B25: e) Ensure adequacy of packing is correct
B27: f) Tighten gland nut (ensure number of thread similar before and after)
A29: Checked by: Name :____________________ Designation : QC Contractor Date :____________________ | K29: Accepted by: Name :____________________ Designation : Area Engineer Date :____________________
A31: Checked by: | J31: Checked by:
A35: Name: | J35: Name:
A37: Designation: QC Contractor | J37: Designation: Area Engineer
A39: Date: | J39: Date:

Sheet Valve Overhaul Checklist
C1: XX TURNAROUND XX Turnaround and Maintenance Works Quality Control | Q1: 1
C6: Checklist for QC-MST-Valve Overhaul
A8: Equipment Tag No. | C8: =VLOOKUP(Q1,Summary!A1:AH376,9,0) | E8: Work ID | G8: =VLOOKUP(Q1,Summary!A1:AH376,2,0) | J8: Contractor | L8: LENOG SDN BHD | N8: Date | O8: =TODAY()
A9: Work Description | C9: =VLOOKUP(Q1,Summary!A1:AH376,12,0)
A10: QUALITY CHECKS
A11: No. | B11: Action | J11: Accepted | K11: Not Accepted | L11: NA | M11: Remarks
B12: Preparation
A13: 1 | B13: Valve assembly as per drawing
A14: 2 | B14: Spare parts kit as per list/drawing (if applicable)
B15: Servicing/overhaul
A16: 3 | B16: Valve Removal
B17: Installation
A18: 4 | B18: Valve flow direction (applicable to globe and check valve)
A19: 5 | B19: Packing of gland
B20: a) Size of packing
B21: b) Type/material of packing
B22: c) Joint design
B23: e) Cleanliness of the stuffing box
A24: 6 | B24: Bonnet
B25: a) Material and size of bonnet gasket
B26: b) Controlled bolting (if applicable)
A27: 7 | B27: Replacement/repair of valve trim:
B28: a) Welding rod for tack welding : ___________
B29: b) Post machining dimensions of trim parts are within tolerance
B30: c) Fitting of trim parts
A31: 8 | B31: Seat Leakage Test
A32: 9 | B32: Body Leak Test
A33: AS LEFT TEST
A35: No. | B35: Item | J35: Accepted | K35: Not Accepted | L35: NA | M35: Remarks
A36: 1 | B36: Type : Ball / Globe / Butterfly / Other :__________ | M36: Refer HT reports No:
A37: 2 | B37: Size/Rating : __________ | M37: Refer HT reports No:
A38: 3 | B38: Medium : __________ | M38: Refer HT reports No:
A39: 4 | B39: Test Pressure (bar) : __________ | M39: Refer HT reports No:
A40: 5 | B40: Holding Time :__________ | M40: Refer HT reports No:
A41: 6 | B41: Allowable leakage (L/Min) :__________ | M41: Refer HT reports No:
A42: 7 | B42: Actual leakage (L/Min) :__________ | M42: Refer HT reports No:
A44: Checked by: Name :____________________ Designation : QC Inspector Date :____________________ | I44: Accepted by : Name :____________________ Designation : Area Engineer Date :____________________
A45: Checked by: | J45: Checked by:
A47: Name: | J47: Name:
A48: Designation: QC Contractor | J48: Designation: Area Engineer
...

Sheet Tagging
L1: 5 | M1: 6 | N1: 7 | O1: 8
A6: Work Order | C6: =IF(VLOOKUP($L$1,Summary!$A$2:$AK$600,2,0)= 0,"", VLOOKUP($L$1,Summary!$A$2:$AK$600,2,0)) | G6: Work Order | I6: =IF(VLOOKUP($M$1,Summary!$A$2:$AK$600,2,0)= 0,"", VLOOKUP($M$1,Summary!$A$2:$AK$600,2,0))
N7: 2
N8: 10
A9: Tag Number | C9: =IF(VLOOKUP($L$1,Summary!$A$2:$AK$600,10,0)= 0,"", VLOOKUP($L$1,Summary!$A$2:$AK$600,10,0)) | G9: Tag Number | I9: =IF(VLOOKUP($M$1,Summary!$A$2:$AK$600,10,0)= 0,"", VLOOKUP($M$1,Summary!$A$2:$AK$600,10,0)) | N9: 4
N10: 5
N11: 6
A12: Area | C12: =IF(VLOOKUP($L$1,Summary!$A$2:$AK$600,4,0)= 0,"", VLOOKUP($L$1,Summary!$A$2:$AK$600,4,0)) | G12: Area | I12: =IF(VLOOKUP($M$1,Summary!$A$2:$AK$600,4,0)= 0,"", VLOOKUP($M$1,Summary!$A$2:$AK$600,4,0)) | N12: 23
N13: 13
A15: Unit | C15: =IF(VLOOKUP($L$1,Summary!$A$2:$AK$600,5,0)=0,"",VLOOKUP($L$1,Summary!$A$2:$AK$600,5,0)) | G15: Unit | I15: =IF(VLOOKUP($M$1,Summary!$A$2:$AK$600,5,0)= 0,"", VLOOKUP($M$1,Summary!$A$2:$AK$600,5,0))
A18: Valve Type | C18: =IF(VLOOKUP($L$1,Summary!$A$2:$AK$600,6,0)= 0,"", VLOOKUP($L$1,Summary!$A$2:$AK$600,6,0)) | G18: Valve Type | I18: =IF(VLOOKUP($M$1,Summary!$A$2:$AK$600,6,0)= 0,"", VLOOKUP($M$1,Summary!$A$2:$AK$600,6,0))
A21: Size | C21: =IF(VLOOKUP($L$1,Summary!$A$2:$AK$600,23,0)= 0,"", VLOOKUP($L$1,Summary!$A$2:$AK$600,23,0)) | G21: Size | I21: =IF(VLOOKUP($M$1,Summary!$A$2:$AK$600,23,0)= 0,"", VLOOKUP($M$1,Summary!$A$2:$AK$600,23,0))
A24: Service Type | C24: =IF(VLOOKUP($L$1,Summary!$A$2:$AK$600,13,0)= 0,"", VLOOKUP($L$1,Summary!$A$2:$AK$600,13,0)) | G24: Service Type | I24: =IF(VLOOKUP($M$1,Summary!$A$2:$AK$600,13,0)= 0,"", VLOOKUP($M$1,Summary!$A$2:$AK$600,13,0))
A32: Work Order | C32: =IF(VLOOKUP($N$1,Summary!$A$2:$AK$600,2,0)= 0,"", VLOOKUP($N$1,Summary!$A$2:$AK$600,2,0)) | G32: Work Order | I32: =IF(VLOOKUP($O$1,Summary!$A$2:$AK$600,2,0)= 0,"", VLOOKUP($O$1,Summary!$A$2:$AK$600,2,0))
A35: Tag Number | C35: =IF(VLOOKUP($N$1,Summary!$A$2:$AK$600,10,0)= 0,"", VLOOKUP($N$1,Summary!$A$2:$AK$600,10,0)) | G35: Tag Number | I35: =IF(VLOOKUP($O$1,Summary!$A$2:$AK$600,10,0)= 0,"", VLOOKUP($O$1,Summary!$A$2:$AK$600,10,0))
A38: Area | C38: =IF(VLOOKUP($N$1,Summary!$A$2:$AK$600,4,0)= 0,"", VLOOKUP($N$1,Summary!$A$2:$AK$600,4,0)) | G38: Area | I38: =IF(VLOOKUP($O$1,Summary!$A$2:$AK$600,4,0)= 0,"", VLOOKUP($O$1,Summary!$A$2:$AK$600,4,0)) | M38: 2
M39: 10
M40: 4
A41: Unit | C41: =IF(VLOOKUP($N$1,Summary!$A$2:$AK$600,5,0)= 0,"", VLOOKUP($N$1,Summary!$A$2:$AK$600,5,0)) | G41: Unit | I41: =IF(VLOOKUP($O$1,Summary!$A$2:$AK$600,5,0)= 0,"", VLOOKUP($O$1,Summary!$A$2:$AK$600,5,0)) | M41: 5
M42: 6
M43: 23
A44: Valve Type | C44: =IF(VLOOKUP($N$1,Summary!$A$2:$AK$600,6,0)= 0,"", VLOOKUP($N$1,Summary!$A$2:$AK$600,6,0)) | G44: Valve Type | I44: =IF(VLOOKUP($O$1,Summary!$A$2:$AK$600,6,0)= 0,"", VLOOKUP($O$1,Summary!$A$2:$AK$600,6,0)) | M44: 13
A47: Size | C47: =IF(VLOOKUP($N$1,Summary!$A$2:$AK$600,23,0)= 0,"", VLOOKUP($N$1,Summary!$A$2:$AK$600,23,0)) | G47: Size | I47: =IF(VLOOKUP($O$1,Summary!$A$2:$AK$600,23,0)= 0,"", VLOOKUP($O$1,Summary!$A$2:$AK$600,23,0))
A50: Service Type | C50: =IF(VLOOKUP($N$1,Summary!$A$2:$AK$600,13,0)= 0,"", VLOOKUP($N$1,Summary!$A$2:$AK$600,13,0)) | G50: Service Type | I50: =IF(VLOOKUP($O$1,Summary!$A$2:$AK$600,13,0)= 0,"", VLOOKUP($O$1,Summary!$A$2:$AK$600,13,0))
